loading app /home/jakob/test_ovs/TLSonSGX/SDN_Controller/learning_switch.py
loading app ryu.controller.ofp_handler
instantiating app ryu.controller.ofp_handler of OFPHandler
instantiating app /home/jakob/test_ovs/TLSonSGX/SDN_Controller/learning_switch.py of SimpleSwitch
hub: uncaught exception: Traceback (most recent call last):
  File "/usr/local/lib/python2.7/dist-packages/ryu/lib/hub.py", line 59, in _launch
    return func(*args, **kwargs)
  File "/usr/local/lib/python2.7/dist-packages/ryu/lib/hub.py", line 131, in wrap_and_handle
    handle(ssl.wrap_socket(sock, **ssl_args), addr)
  File "/usr/local/lib/python2.7/dist-packages/eventlet/green/ssl.py", line 369, in wrap_socket
    return GreenSSLSocket(sock, *a, **kw)
  File "/usr/local/lib/python2.7/dist-packages/eventlet/green/ssl.py", line 64, in __init__
    ca_certs, do_handshake_on_connect and six.PY2, *args, **kw)
  File "/usr/lib/python2.7/ssl.py", line 542, in __init__
    self._context.load_verify_locations(ca_certs)
IOError: [Errno 2] No such file or directory

hub: uncaught exception: Traceback (most recent call last):
  File "/usr/local/lib/python2.7/dist-packages/ryu/lib/hub.py", line 59, in _launch
    return func(*args, **kwargs)
  File "/usr/local/lib/python2.7/dist-packages/ryu/lib/hub.py", line 131, in wrap_and_handle
    handle(ssl.wrap_socket(sock, **ssl_args), addr)
  File "/usr/local/lib/python2.7/dist-packages/eventlet/green/ssl.py", line 369, in wrap_socket
    return GreenSSLSocket(sock, *a, **kw)
  File "/usr/local/lib/python2.7/dist-packages/eventlet/green/ssl.py", line 64, in __init__
    ca_certs, do_handshake_on_connect and six.PY2, *args, **kw)
  File "/usr/lib/python2.7/ssl.py", line 542, in __init__
    self._context.load_verify_locations(ca_certs)
IOError: [Errno 2] No such file or directory

hub: uncaught exception: Traceback (most recent call last):
  File "/usr/local/lib/python2.7/dist-packages/ryu/lib/hub.py", line 59, in _launch
    return func(*args, **kwargs)
  File "/usr/local/lib/python2.7/dist-packages/ryu/lib/hub.py", line 131, in wrap_and_handle
    handle(ssl.wrap_socket(sock, **ssl_args), addr)
  File "/usr/local/lib/python2.7/dist-packages/eventlet/green/ssl.py", line 369, in wrap_socket
    return GreenSSLSocket(sock, *a, **kw)
  File "/usr/local/lib/python2.7/dist-packages/eventlet/green/ssl.py", line 64, in __init__
    ca_certs, do_handshake_on_connect and six.PY2, *args, **kw)
  File "/usr/lib/python2.7/ssl.py", line 542, in __init__
    self._context.load_verify_locations(ca_certs)
IOError: [Errno 2] No such file or directory

hub: uncaught exception: Traceback (most recent call last):
  File "/usr/local/lib/python2.7/dist-packages/ryu/lib/hub.py", line 59, in _launch
    return func(*args, **kwargs)
  File "/usr/local/lib/python2.7/dist-packages/ryu/lib/hub.py", line 131, in wrap_and_handle
    handle(ssl.wrap_socket(sock, **ssl_args), addr)
  File "/usr/local/lib/python2.7/dist-packages/eventlet/green/ssl.py", line 369, in wrap_socket
    return GreenSSLSocket(sock, *a, **kw)
  File "/usr/local/lib/python2.7/dist-packages/eventlet/green/ssl.py", line 64, in __init__
    ca_certs, do_handshake_on_connect and six.PY2, *args, **kw)
  File "/usr/lib/python2.7/ssl.py", line 542, in __init__
    self._context.load_verify_locations(ca_certs)
IOError: [Errno 2] No such file or directory

hub: uncaught exception: Traceback (most recent call last):
  File "/usr/local/lib/python2.7/dist-packages/ryu/lib/hub.py", line 59, in _launch
    return func(*args, **kwargs)
  File "/usr/local/lib/python2.7/dist-packages/ryu/lib/hub.py", line 131, in wrap_and_handle
    handle(ssl.wrap_socket(sock, **ssl_args), addr)
  File "/usr/local/lib/python2.7/dist-packages/eventlet/green/ssl.py", line 369, in wrap_socket
    return GreenSSLSocket(sock, *a, **kw)
  File "/usr/local/lib/python2.7/dist-packages/eventlet/green/ssl.py", line 64, in __init__
    ca_certs, do_handshake_on_connect and six.PY2, *args, **kw)
  File "/usr/lib/python2.7/ssl.py", line 542, in __init__
    self._context.load_verify_locations(ca_certs)
IOError: [Errno 2] No such file or directory

hub: uncaught exception: Traceback (most recent call last):
  File "/usr/local/lib/python2.7/dist-packages/ryu/lib/hub.py", line 59, in _launch
    return func(*args, **kwargs)
  File "/usr/local/lib/python2.7/dist-packages/ryu/lib/hub.py", line 131, in wrap_and_handle
    handle(ssl.wrap_socket(sock, **ssl_args), addr)
  File "/usr/local/lib/python2.7/dist-packages/eventlet/green/ssl.py", line 369, in wrap_socket
    return GreenSSLSocket(sock, *a, **kw)
  File "/usr/local/lib/python2.7/dist-packages/eventlet/green/ssl.py", line 64, in __init__
    ca_certs, do_handshake_on_connect and six.PY2, *args, **kw)
  File "/usr/lib/python2.7/ssl.py", line 542, in __init__
    self._context.load_verify_locations(ca_certs)
IOError: [Errno 2] No such file or directory

hub: uncaught exception: Traceback (most recent call last):
  File "/usr/local/lib/python2.7/dist-packages/ryu/lib/hub.py", line 59, in _launch
    return func(*args, **kwargs)
  File "/usr/local/lib/python2.7/dist-packages/ryu/lib/hub.py", line 131, in wrap_and_handle
    handle(ssl.wrap_socket(sock, **ssl_args), addr)
  File "/usr/local/lib/python2.7/dist-packages/eventlet/green/ssl.py", line 369, in wrap_socket
    return GreenSSLSocket(sock, *a, **kw)
  File "/usr/local/lib/python2.7/dist-packages/eventlet/green/ssl.py", line 64, in __init__
    ca_certs, do_handshake_on_connect and six.PY2, *args, **kw)
  File "/usr/lib/python2.7/ssl.py", line 542, in __init__
    self._context.load_verify_locations(ca_certs)
IOError: [Errno 2] No such file or directory

hub: uncaught exception: Traceback (most recent call last):
  File "/usr/local/lib/python2.7/dist-packages/ryu/lib/hub.py", line 59, in _launch
    return func(*args, **kwargs)
  File "/usr/local/lib/python2.7/dist-packages/ryu/lib/hub.py", line 131, in wrap_and_handle
    handle(ssl.wrap_socket(sock, **ssl_args), addr)
  File "/usr/local/lib/python2.7/dist-packages/eventlet/green/ssl.py", line 369, in wrap_socket
    return GreenSSLSocket(sock, *a, **kw)
  File "/usr/local/lib/python2.7/dist-packages/eventlet/green/ssl.py", line 64, in __init__
    ca_certs, do_handshake_on_connect and six.PY2, *args, **kw)
  File "/usr/lib/python2.7/ssl.py", line 542, in __init__
    self._context.load_verify_locations(ca_certs)
IOError: [Errno 2] No such file or directory

hub: uncaught exception: Traceback (most recent call last):
  File "/usr/local/lib/python2.7/dist-packages/ryu/lib/hub.py", line 59, in _launch
    return func(*args, **kwargs)
  File "/usr/local/lib/python2.7/dist-packages/ryu/lib/hub.py", line 131, in wrap_and_handle
    handle(ssl.wrap_socket(sock, **ssl_args), addr)
  File "/usr/local/lib/python2.7/dist-packages/eventlet/green/ssl.py", line 369, in wrap_socket
    return GreenSSLSocket(sock, *a, **kw)
  File "/usr/local/lib/python2.7/dist-packages/eventlet/green/ssl.py", line 64, in __init__
    ca_certs, do_handshake_on_connect and six.PY2, *args, **kw)
  File "/usr/lib/python2.7/ssl.py", line 542, in __init__
    self._context.load_verify_locations(ca_certs)
IOError: [Errno 2] No such file or directory

hub: uncaught exception: Traceback (most recent call last):
  File "/usr/local/lib/python2.7/dist-packages/ryu/lib/hub.py", line 59, in _launch
    return func(*args, **kwargs)
  File "/usr/local/lib/python2.7/dist-packages/ryu/lib/hub.py", line 131, in wrap_and_handle
    handle(ssl.wrap_socket(sock, **ssl_args), addr)
  File "/usr/local/lib/python2.7/dist-packages/eventlet/green/ssl.py", line 369, in wrap_socket
    return GreenSSLSocket(sock, *a, **kw)
  File "/usr/local/lib/python2.7/dist-packages/eventlet/green/ssl.py", line 64, in __init__
    ca_certs, do_handshake_on_connect and six.PY2, *args, **kw)
  File "/usr/lib/python2.7/ssl.py", line 542, in __init__
    self._context.load_verify_locations(ca_certs)
IOError: [Errno 2] No such file or directory

hub: uncaught exception: Traceback (most recent call last):
  File "/usr/local/lib/python2.7/dist-packages/ryu/lib/hub.py", line 59, in _launch
    return func(*args, **kwargs)
  File "/usr/local/lib/python2.7/dist-packages/ryu/lib/hub.py", line 131, in wrap_and_handle
    handle(ssl.wrap_socket(sock, **ssl_args), addr)
  File "/usr/local/lib/python2.7/dist-packages/eventlet/green/ssl.py", line 369, in wrap_socket
    return GreenSSLSocket(sock, *a, **kw)
  File "/usr/local/lib/python2.7/dist-packages/eventlet/green/ssl.py", line 64, in __init__
    ca_certs, do_handshake_on_connect and six.PY2, *args, **kw)
  File "/usr/lib/python2.7/ssl.py", line 542, in __init__
    self._context.load_verify_locations(ca_certs)
IOError: [Errno 2] No such file or directory

hub: uncaught exception: Traceback (most recent call last):
  File "/usr/local/lib/python2.7/dist-packages/ryu/lib/hub.py", line 59, in _launch
    return func(*args, **kwargs)
  File "/usr/local/lib/python2.7/dist-packages/ryu/lib/hub.py", line 131, in wrap_and_handle
    handle(ssl.wrap_socket(sock, **ssl_args), addr)
  File "/usr/local/lib/python2.7/dist-packages/eventlet/green/ssl.py", line 369, in wrap_socket
    return GreenSSLSocket(sock, *a, **kw)
  File "/usr/local/lib/python2.7/dist-packages/eventlet/green/ssl.py", line 64, in __init__
    ca_certs, do_handshake_on_connect and six.PY2, *args, **kw)
  File "/usr/lib/python2.7/ssl.py", line 542, in __init__
    self._context.load_verify_locations(ca_certs)
IOError: [Errno 2] No such file or directory

hub: uncaught exception: Traceback (most recent call last):
  File "/usr/local/lib/python2.7/dist-packages/ryu/lib/hub.py", line 59, in _launch
    return func(*args, **kwargs)
  File "/usr/local/lib/python2.7/dist-packages/ryu/lib/hub.py", line 131, in wrap_and_handle
    handle(ssl.wrap_socket(sock, **ssl_args), addr)
  File "/usr/local/lib/python2.7/dist-packages/eventlet/green/ssl.py", line 369, in wrap_socket
    return GreenSSLSocket(sock, *a, **kw)
  File "/usr/local/lib/python2.7/dist-packages/eventlet/green/ssl.py", line 64, in __init__
    ca_certs, do_handshake_on_connect and six.PY2, *args, **kw)
  File "/usr/lib/python2.7/ssl.py", line 542, in __init__
    self._context.load_verify_locations(ca_certs)
IOError: [Errno 2] No such file or directory

