loading app /home/jakob/ovs-sgx/SDN_Controller/not_learning_switch.py
loading app ryu.controller.ofp_handler
instantiating app /home/jakob/ovs-sgx/SDN_Controller/not_learning_switch.py of SimpleSwitch
instantiating app ryu.controller.ofp_handler of OFPHandler
BRICK SimpleSwitch
  CONSUMES EventOFPPacketIn
  CONSUMES EventOFPPortStatus
BRICK ofp_event
  PROVIDES EventOFPPacketIn TO {'SimpleSwitch': set(['main'])}
  PROVIDES EventOFPPortStatus TO {'SimpleSwitch': set(['main'])}
  CONSUMES EventOFPPortDescStatsReply
  CONSUMES EventOFPPortStatus
  CONSUMES EventOFPSwitchFeatures
  CONSUMES EventOFPErrorMsg
  CONSUMES EventOFPEchoRequest
  CONSUMES EventOFPEchoReply
  CONSUMES EventOFPHello
hub: uncaught exception: Traceback (most recent call last):
  File "/usr/local/lib/python2.7/dist-packages/ryu/lib/hub.py", line 59, in _launch
    return func(*args, **kwargs)
  File "/usr/local/lib/python2.7/dist-packages/ryu/controller/controller.py", line 176, in server_loop
    ssl_version=ssl.PROTOCOL_TLSv1)
  File "/usr/local/lib/python2.7/dist-packages/ryu/lib/hub.py", line 126, in __init__
    self.server = eventlet.listen(listen_info)
  File "/usr/local/lib/python2.7/dist-packages/eventlet/convenience.py", line 78, in listen
    sock.bind(addr)
  File "/usr/lib/python2.7/socket.py", line 228, in meth
    return getattr(self._sock,name)(*args)
error: [Errno 98] Address already in use

hub: uncaught exception: Traceback (most recent call last):
  File "/usr/local/lib/python2.7/dist-packages/ryu/lib/hub.py", line 59, in _launch
    return func(*args, **kwargs)
  File "/usr/local/lib/python2.7/dist-packages/ryu/controller/controller.py", line 153, in __call__
    self.ofp_ssl_listen_port)
  File "/usr/local/lib/python2.7/dist-packages/ryu/controller/controller.py", line 176, in server_loop
    ssl_version=ssl.PROTOCOL_TLSv1)
  File "/usr/local/lib/python2.7/dist-packages/ryu/lib/hub.py", line 126, in __init__
    self.server = eventlet.listen(listen_info)
  File "/usr/local/lib/python2.7/dist-packages/eventlet/convenience.py", line 78, in listen
    sock.bind(addr)
  File "/usr/lib/python2.7/socket.py", line 228, in meth
    return getattr(self._sock,name)(*args)
error: [Errno 98] Address already in use

